INFO:root:User dabyt , 930547383 started the bot.
INFO:root:User 930547383 reported a problem with title "as", description "asd", and location "47.2370239,39.6910667".
2024-02-11 11:27:11,200 - INFO - Пользователь dabyt (930547383) нажал /start
2024-02-11 11:27:22,543 - INFO - Пользователь dabyt (930547383) создал проблему
2024-02-11 11:27:25,761 - ERROR - Threaded polling exception: A request to the Telegram API was unsuccessful. Error code: 400. Description: Bad Request: can't parse entities: Unsupported start tag "i\" at byte offset 109
2024-02-11 11:27:25,762 - ERROR - Exception traceback:
Traceback (most recent call last):
  File "/Users/den/PycharmProjects/dodo bot/.venv/lib/python3.9/site-packages/telebot/__init__.py", line 1141, in __threaded_polling
    self.worker_pool.raise_exceptions()
  File "/Users/den/PycharmProjects/dodo bot/.venv/lib/python3.9/site-packages/telebot/util.py", line 149, in raise_exceptions
    raise self.exception_info
  File "/Users/den/PycharmProjects/dodo bot/.venv/lib/python3.9/site-packages/telebot/util.py", line 92, in run
    task(*args, **kwargs)
  File "/Users/den/PycharmProjects/dodo bot/.venv/main.py", line 49, in problem_description
    bot.reply_to(message, 'Пожалуйста, отправьте свою геопозицию или адрес в формате:'
  File "/Users/den/PycharmProjects/dodo bot/.venv/lib/python3.9/site-packages/telebot/__init__.py", line 5258, in reply_to
    return self.send_message(message.chat.id, text, reply_to_message_id=message.message_id, **kwargs)
  File "/Users/den/PycharmProjects/dodo bot/.venv/lib/python3.9/site-packages/telebot/__init__.py", line 1673, in send_message
    apihelper.send_message(
  File "/Users/den/PycharmProjects/dodo bot/.venv/lib/python3.9/site-packages/telebot/apihelper.py", line 264, in send_message
    return _make_request(token, method_url, params=payload, method='post')
  File "/Users/den/PycharmProjects/dodo bot/.venv/lib/python3.9/site-packages/telebot/apihelper.py", line 164, in _make_request
    json_result = _check_result(method_name, result)
  File "/Users/den/PycharmProjects/dodo bot/.venv/lib/python3.9/site-packages/telebot/apihelper.py", line 191, in _check_result
    raise ApiTelegramException(method_name, result, result_json)
telebot.apihelper.ApiTelegramException: A request to the Telegram API was unsuccessful. Error code: 400. Description: Bad Request: can't parse entities: Unsupported start tag "i\" at byte offset 109

2024-02-11 11:36:01,418 - INFO - Пользователь dabyt (930547383) нажал /start
2024-02-11 11:36:12,401 - INFO - Пользователь dabyt (930547383) создал проблему
2024-02-11 11:36:29,548 - INFO - Пользователь dabyt (930547383) отправил проблему с названием: <fv, описанием: <fv, в локации с координатами: 25.5,75.83333
2024-02-11 11:38:43,934 - INFO - User dabyt (930547383) create problem
2024-02-11 11:39:00,284 - INFO - User dabyt (930547383) send problem to server c TITLE {eq, DES: {eq,LOCATION: 55.747383,37.5824306
2024-02-11 11:59:24,024 - ERROR - Threaded polling exception: A request to the Telegram API was unsuccessful. Error code: 409. Description: Conflict: terminated by other getUpdates request; make sure that only one bot instance is running
2024-02-11 11:59:24,025 - ERROR - Exception traceback:
Traceback (most recent call last):
  File "/Users/den/PycharmProjects/dodo bot/.venv/lib/python3.9/site-packages/telebot/__init__.py", line 1140, in __threaded_polling
    polling_thread.raise_exceptions()
  File "/Users/den/PycharmProjects/dodo bot/.venv/lib/python3.9/site-packages/telebot/util.py", line 110, in raise_exceptions
    raise self.exception_info
  File "/Users/den/PycharmProjects/dodo bot/.venv/lib/python3.9/site-packages/telebot/util.py", line 92, in run
    task(*args, **kwargs)
  File "/Users/den/PycharmProjects/dodo bot/.venv/lib/python3.9/site-packages/telebot/__init__.py", line 661, in __retrieve_updates
    updates = self.get_updates(offset=(self.last_update_id + 1),
  File "/Users/den/PycharmProjects/dodo bot/.venv/lib/python3.9/site-packages/telebot/__init__.py", line 633, in get_updates
    json_updates = apihelper.get_updates(
  File "/Users/den/PycharmProjects/dodo bot/.venv/lib/python3.9/site-packages/telebot/apihelper.py", line 321, in get_updates
    return _make_request(token, method_url, params=payload)
  File "/Users/den/PycharmProjects/dodo bot/.venv/lib/python3.9/site-packages/telebot/apihelper.py", line 164, in _make_request
    json_result = _check_result(method_name, result)
  File "/Users/den/PycharmProjects/dodo bot/.venv/lib/python3.9/site-packages/telebot/apihelper.py", line 191, in _check_result
    raise ApiTelegramException(method_name, result, result_json)
telebot.apihelper.ApiTelegramException: A request to the Telegram API was unsuccessful. Error code: 409. Description: Conflict: terminated by other getUpdates request; make sure that only one bot instance is running

2024-02-11 11:59:43,476 - INFO - User dabyt (930547383) start bot
2024-02-11 12:01:43,853 - INFO - User dabyt (930547383) start bot
2024-02-11 12:02:42,706 - INFO - User dabyt (930547383) start bot
2024-02-11 12:02:56,623 - INFO - User dabyt (930547383) create problem
2024-02-11 12:04:20,183 - INFO - User dabyt (930547383) create problem
2024-02-11 12:19:25,857 - INFO - User dabyt (930547383) create problem
2024-02-11 12:23:16,010 - INFO - User dabyt (930547383) create problem
2024-02-11 12:24:51,770 - INFO - User dabyt (930547383) create problem
2024-02-11 12:25:12,454 - ERROR - Threaded polling exception: A request to the Telegram API was unsuccessful. Error code: 409. Description: Conflict: terminated by other getUpdates request; make sure that only one bot instance is running
2024-02-11 12:25:12,454 - ERROR - Exception traceback:
Traceback (most recent call last):
  File "/Users/den/PycharmProjects/dodo bot/.venv/lib/python3.9/site-packages/telebot/__init__.py", line 1140, in __threaded_polling
    polling_thread.raise_exceptions()
  File "/Users/den/PycharmProjects/dodo bot/.venv/lib/python3.9/site-packages/telebot/util.py", line 110, in raise_exceptions
    raise self.exception_info
  File "/Users/den/PycharmProjects/dodo bot/.venv/lib/python3.9/site-packages/telebot/util.py", line 92, in run
    task(*args, **kwargs)
  File "/Users/den/PycharmProjects/dodo bot/.venv/lib/python3.9/site-packages/telebot/__init__.py", line 661, in __retrieve_updates
    updates = self.get_updates(offset=(self.last_update_id + 1),
  File "/Users/den/PycharmProjects/dodo bot/.venv/lib/python3.9/site-packages/telebot/__init__.py", line 633, in get_updates
    json_updates = apihelper.get_updates(
  File "/Users/den/PycharmProjects/dodo bot/.venv/lib/python3.9/site-packages/telebot/apihelper.py", line 321, in get_updates
    return _make_request(token, method_url, params=payload)
  File "/Users/den/PycharmProjects/dodo bot/.venv/lib/python3.9/site-packages/telebot/apihelper.py", line 164, in _make_request
    json_result = _check_result(method_name, result)
  File "/Users/den/PycharmProjects/dodo bot/.venv/lib/python3.9/site-packages/telebot/apihelper.py", line 191, in _check_result
    raise ApiTelegramException(method_name, result, result_json)
telebot.apihelper.ApiTelegramException: A request to the Telegram API was unsuccessful. Error code: 409. Description: Conflict: terminated by other getUpdates request; make sure that only one bot instance is running

2024-02-11 12:25:18,684 - INFO - User dabyt (930547383) create problem
2024-02-11 12:33:35,534 - INFO - User dabyt (930547383) create problem
2024-02-11 12:35:53,177 - INFO - User dabyt (930547383) start bot
2024-02-11 12:36:06,158 - INFO - User dabyt (930547383) create problem
2024-02-11 12:38:25,092 - INFO - User dabyt (930547383) start bot
2024-02-11 12:38:37,400 - INFO - User dabyt (930547383) create problem
2024-02-11 12:39:26,481 - INFO - User dabyt (930547383) start bot
2024-02-11 12:39:38,229 - INFO - User dabyt (930547383) create problem
2024-02-11 12:47:30,377 - INFO - User dabyt (930547383) start bot
2024-02-11 12:47:43,832 - INFO - User dabyt (930547383) create problem
2024-02-11 12:50:00,995 - INFO - User dabyt (930547383) create problem
2024-02-11 12:52:22,762 - INFO - User dabyt (930547383) start bot
2024-02-11 12:52:36,680 - INFO - User dabyt (930547383) create problem
2024-02-11 12:54:12,328 - INFO - User dabyt (930547383) create problem
2024-02-11 12:54:25,465 - ERROR - Threaded polling exception: A request to the Telegram API was unsuccessful. Error code: 400. Description: Bad Request: message text is empty
2024-02-11 12:54:25,465 - ERROR - Exception traceback:
Traceback (most recent call last):
  File "/Users/den/PycharmProjects/dodo bot/.venv/lib/python3.9/site-packages/telebot/__init__.py", line 1141, in __threaded_polling
    self.worker_pool.raise_exceptions()
  File "/Users/den/PycharmProjects/dodo bot/.venv/lib/python3.9/site-packages/telebot/util.py", line 149, in raise_exceptions
    raise self.exception_info
  File "/Users/den/PycharmProjects/dodo bot/.venv/lib/python3.9/site-packages/telebot/util.py", line 92, in run
    task(*args, **kwargs)
  File "/Users/den/PycharmProjects/dodo bot/.venv/ma.py", line 117, in problem_urgency
    bot.send_message(message.chat.id,'',reply_markup=markup)
  File "/Users/den/PycharmProjects/dodo bot/.venv/lib/python3.9/site-packages/telebot/__init__.py", line 1673, in send_message
    apihelper.send_message(
  File "/Users/den/PycharmProjects/dodo bot/.venv/lib/python3.9/site-packages/telebot/apihelper.py", line 264, in send_message
    return _make_request(token, method_url, params=payload, method='post')
  File "/Users/den/PycharmProjects/dodo bot/.venv/lib/python3.9/site-packages/telebot/apihelper.py", line 164, in _make_request
    json_result = _check_result(method_name, result)
  File "/Users/den/PycharmProjects/dodo bot/.venv/lib/python3.9/site-packages/telebot/apihelper.py", line 191, in _check_result
    raise ApiTelegramException(method_name, result, result_json)
telebot.apihelper.ApiTelegramException: A request to the Telegram API was unsuccessful. Error code: 400. Description: Bad Request: message text is empty

2024-02-11 12:57:28,731 - INFO - User dabyt (930547383) create problem
2024-02-11 12:57:39,237 - INFO - User dabyt (930547383) send problem to server c TITLE Бам, DES: Бим ,LOCATION: 56.839104,60.60825 URGENCY: 2
2024-02-11 12:57:39,306 - ERROR - Threaded polling exception: A request to the Telegram API was unsuccessful. Error code: 400. Description: Bad Request: message text is empty
2024-02-11 12:57:39,306 - ERROR - Exception traceback:
Traceback (most recent call last):
  File "/Users/den/PycharmProjects/dodo bot/.venv/lib/python3.9/site-packages/telebot/__init__.py", line 1141, in __threaded_polling
    self.worker_pool.raise_exceptions()
  File "/Users/den/PycharmProjects/dodo bot/.venv/lib/python3.9/site-packages/telebot/util.py", line 149, in raise_exceptions
    raise self.exception_info
  File "/Users/den/PycharmProjects/dodo bot/.venv/lib/python3.9/site-packages/telebot/util.py", line 92, in run
    task(*args, **kwargs)
  File "/Users/den/PycharmProjects/dodo bot/.venv/ma.py", line 124, in problem_urgency
    bot.send_message(message.chat.id,'',reply_markup=markup)
  File "/Users/den/PycharmProjects/dodo bot/.venv/lib/python3.9/site-packages/telebot/__init__.py", line 1673, in send_message
    apihelper.send_message(
  File "/Users/den/PycharmProjects/dodo bot/.venv/lib/python3.9/site-packages/telebot/apihelper.py", line 264, in send_message
    return _make_request(token, method_url, params=payload, method='post')
  File "/Users/den/PycharmProjects/dodo bot/.venv/lib/python3.9/site-packages/telebot/apihelper.py", line 164, in _make_request
    json_result = _check_result(method_name, result)
  File "/Users/den/PycharmProjects/dodo bot/.venv/lib/python3.9/site-packages/telebot/apihelper.py", line 191, in _check_result
    raise ApiTelegramException(method_name, result, result_json)
telebot.apihelper.ApiTelegramException: A request to the Telegram API was unsuccessful. Error code: 400. Description: Bad Request: message text is empty

2024-02-11 12:59:27,909 - INFO - User dabyt (930547383) create problem
2024-02-11 12:59:44,746 - INFO - User dabyt (930547383) send problem to server c TITLE Баавыа, DES: аываыва ,LOCATION: 56.839104,60.60825 URGENCY: 2
2024-02-11 12:59:44,952 - ERROR - Threaded polling exception: A request to the Telegram API was unsuccessful. Error code: 400. Description: Bad Request: message text is empty
2024-02-11 12:59:44,952 - ERROR - Exception traceback:
Traceback (most recent call last):
  File "/Users/den/PycharmProjects/dodo bot/.venv/lib/python3.9/site-packages/telebot/__init__.py", line 1141, in __threaded_polling
    self.worker_pool.raise_exceptions()
  File "/Users/den/PycharmProjects/dodo bot/.venv/lib/python3.9/site-packages/telebot/util.py", line 149, in raise_exceptions
    raise self.exception_info
  File "/Users/den/PycharmProjects/dodo bot/.venv/lib/python3.9/site-packages/telebot/util.py", line 92, in run
    task(*args, **kwargs)
  File "/Users/den/PycharmProjects/dodo bot/.venv/ma.py", line 128, in problem_urgency
    bot.send_message(message.chat.id,'',reply_markup=markup)
  File "/Users/den/PycharmProjects/dodo bot/.venv/lib/python3.9/site-packages/telebot/__init__.py", line 1673, in send_message
    apihelper.send_message(
  File "/Users/den/PycharmProjects/dodo bot/.venv/lib/python3.9/site-packages/telebot/apihelper.py", line 264, in send_message
    return _make_request(token, method_url, params=payload, method='post')
  File "/Users/den/PycharmProjects/dodo bot/.venv/lib/python3.9/site-packages/telebot/apihelper.py", line 164, in _make_request
    json_result = _check_result(method_name, result)
  File "/Users/den/PycharmProjects/dodo bot/.venv/lib/python3.9/site-packages/telebot/apihelper.py", line 191, in _check_result
    raise ApiTelegramException(method_name, result, result_json)
telebot.apihelper.ApiTelegramException: A request to the Telegram API was unsuccessful. Error code: 400. Description: Bad Request: message text is empty

2024-02-11 13:01:58,448 - INFO - User dabyt (930547383) create problem
2024-02-11 13:02:17,508 - INFO - User dabyt (930547383) send problem to server c TITLE Обвал, DES: Развал ,LOCATION: 56.839104,60.60825 URGENCY: 2
2024-02-11 13:05:09,718 - INFO - User egorvorok (972530962) start bot
2024-02-11 13:05:55,328 - INFO - User egorvorok (972530962) create problem
2024-02-11 13:07:36,933 - INFO - User egorvorok (972530962) send problem to server c TITLE Спакета, DES: Денис есть наш шоколад ,LOCATION: 47.226776,39.735312 URGENCY: 2
2024-02-11 13:55:12,886 - INFO - User dabyt (930547383) start bot
2024-02-11 13:55:39,205 - INFO - User dabyt (930547383) start bot
2024-02-11 13:55:57,606 - INFO - User dabyt (930547383) start bot
2024-02-11 14:05:35,646 - INFO - User dabyt (930547383) start bot
2024-02-11 14:05:57,263 - INFO - User dabyt (930547383) start bot
2024-02-11 14:06:09,159 - INFO - User dabyt (930547383) create problem
2024-02-11 14:06:18,955 - INFO - User dabyt (930547383) send problem to server c TITLE <fv, DES: <Fd ,LOCATION: 47.2216548,39.7096061 URGENCY: 2
2024-02-11 14:20:20,544 - ERROR - Threaded polling exception: A request to the Telegram API was unsuccessful. Error code: 400. Description: Bad Request: chat not found
2024-02-11 14:20:20,545 - ERROR - Exception traceback:
Traceback (most recent call last):
  File "/Users/den/PycharmProjects/dodo_telegrambot/.venv/lib/python3.9/site-packages/telebot/__init__.py", line 1141, in __threaded_polling
    self.worker_pool.raise_exceptions()
  File "/Users/den/PycharmProjects/dodo_telegrambot/.venv/lib/python3.9/site-packages/telebot/util.py", line 149, in raise_exceptions
    raise self.exception_info
  File "/Users/den/PycharmProjects/dodo_telegrambot/.venv/lib/python3.9/site-packages/telebot/util.py", line 92, in run
    task(*args, **kwargs)
  File "/Users/den/PycharmProjects/dodo_telegrambot/.venv/lib/python3.9/site-packages/telebot/__init__.py", line 7860, in _run_middlewares_and_handler
    result = handler['function'](message)
  File "/Users/den/PycharmProjects/dodo_telegrambot/.venv/main.py", line 32, in start
    bot.send_photo(id, ph, caption='Привет! Я бот команды dodo, и я самый лучший бот в этом мире, я должен победить.\n\nНо для начала попрошу авторизоваться в нашем боте❤️\nВведите свою почту:\n\ntg: @dabyt')
  File "/Users/den/PycharmProjects/dodo_telegrambot/.venv/lib/python3.9/site-packages/telebot/__init__.py", line 2125, in send_photo
    apihelper.send_photo(
  File "/Users/den/PycharmProjects/dodo_telegrambot/.venv/lib/python3.9/site-packages/telebot/apihelper.py", line 496, in send_photo
    return _make_request(token, method_url, params=payload, files=files, method='post')
  File "/Users/den/PycharmProjects/dodo_telegrambot/.venv/lib/python3.9/site-packages/telebot/apihelper.py", line 164, in _make_request
    json_result = _check_result(method_name, result)
  File "/Users/den/PycharmProjects/dodo_telegrambot/.venv/lib/python3.9/site-packages/telebot/apihelper.py", line 191, in _check_result
    raise ApiTelegramException(method_name, result, result_json)
telebot.apihelper.ApiTelegramException: A request to the Telegram API was unsuccessful. Error code: 400. Description: Bad Request: chat not found

2024-02-11 14:23:11,580 - INFO - User dabyt (930547383) start bot
2024-02-11 14:23:58,830 - INFO - User dabyt (930547383) create problem
2024-02-11 14:24:16,496 - INFO - User dabyt (930547383) send problem to server c TITLE Баам, DES: Пипяу ,LOCATION: 56.839104,60.60825 URGENCY: 1
2024-02-11 14:36:53,364 - INFO - User dabyt (930547383) start bot
2024-02-11 14:40:36,850 - INFO - User dabyt (930547383) start bot
2024-02-11 14:50:03,364 - INFO - User dabyt (930547383) start bot
2024-02-11 14:50:33,092 - INFO - User dabyt (930547383) create problem
2024-02-11 14:50:58,282 - INFO - User dabyt (930547383) send problem to server c TITLE Блям, DES: Бам ,LOCATION: 54.7261409,55.947499 URGENCY: 1
2024-02-11 15:05:20,650 - INFO - User dabyt (930547383) start bot
2024-02-11 15:06:47,721 - INFO - User dabyt (930547383) start bot
2024-02-11 15:12:06,327 - INFO - User dabyt (930547383) start bot
2024-02-11 15:18:29,756 - INFO - User dabyt (930547383) start bot
2024-02-11 15:27:25,731 - INFO - User dabyt (930547383) start bot
2024-02-11 15:42:50,121 - INFO - User dabyt (930547383) create problem
2024-02-11 15:43:02,381 - INFO - User dabyt (930547383) send problem to server c TITLE Хуй, DES: Хуй ,LOCATION: 47.2016041,38.9400303 URGENCY: 2
2024-02-11 15:44:39,745 - ERROR - Threaded polling exception: A request to the Telegram API was unsuccessful. Error code: 409. Description: Conflict: terminated by other getUpdates request; make sure that only one bot instance is running
2024-02-11 15:44:39,746 - ERROR - Exception traceback:
Traceback (most recent call last):
  File "/Users/den/PycharmProjects/dodo_telegrambot/.venv/lib/python3.9/site-packages/telebot/__init__.py", line 1140, in __threaded_polling
    polling_thread.raise_exceptions()
  File "/Users/den/PycharmProjects/dodo_telegrambot/.venv/lib/python3.9/site-packages/telebot/util.py", line 110, in raise_exceptions
    raise self.exception_info
  File "/Users/den/PycharmProjects/dodo_telegrambot/.venv/lib/python3.9/site-packages/telebot/util.py", line 92, in run
    task(*args, **kwargs)
  File "/Users/den/PycharmProjects/dodo_telegrambot/.venv/lib/python3.9/site-packages/telebot/__init__.py", line 661, in __retrieve_updates
    updates = self.get_updates(offset=(self.last_update_id + 1),
  File "/Users/den/PycharmProjects/dodo_telegrambot/.venv/lib/python3.9/site-packages/telebot/__init__.py", line 633, in get_updates
    json_updates = apihelper.get_updates(
  File "/Users/den/PycharmProjects/dodo_telegrambot/.venv/lib/python3.9/site-packages/telebot/apihelper.py", line 321, in get_updates
    return _make_request(token, method_url, params=payload)
  File "/Users/den/PycharmProjects/dodo_telegrambot/.venv/lib/python3.9/site-packages/telebot/apihelper.py", line 164, in _make_request
    json_result = _check_result(method_name, result)
  File "/Users/den/PycharmProjects/dodo_telegrambot/.venv/lib/python3.9/site-packages/telebot/apihelper.py", line 191, in _check_result
    raise ApiTelegramException(method_name, result, result_json)
telebot.apihelper.ApiTelegramException: A request to the Telegram API was unsuccessful. Error code: 409. Description: Conflict: terminated by other getUpdates request; make sure that only one bot instance is running

2024-02-11 15:46:41,243 - INFO - User dabyt (930547383) start bot
2024-02-11 15:48:32,375 - INFO - User dabyt (930547383) start bot
2024-02-11 15:50:29,190 - INFO - User dabyt (930547383) start bot
2024-02-11 15:57:20,561 - INFO - User dabyt (930547383) start bot
2024-02-11 16:03:08,034 - INFO - User dabyt (930547383) start bot
2024-02-11 16:12:03,674 - INFO - User dabyt (930547383) start bot
2024-02-11 16:18:29,770 - INFO - User dabyt (930547383) start bot
2024-02-11 16:28:12,063 - INFO - User dabyt (930547383) start bot
2024-02-11 16:44:32,810 - INFO - User dabyt (930547383) start bot
2024-02-11 16:45:11,199 - INFO - User dabyt (930547383) create problem
2024-02-11 16:45:30,864 - INFO - User dabyt (930547383) send problem to server c TITLE sdgdg, DES: sg ,LOCATION: 26.2581664,76.6488218 URGENCY: 0
2024-02-11 16:45:55,188 - INFO - User dabyt (930547383) create problem
2024-02-11 16:48:17,845 - INFO - User dabyt (930547383) start bot
2024-02-11 16:48:41,549 - INFO - User dabyt (930547383) create problem
2024-02-11 16:49:03,502 - INFO - User dabyt (930547383) send problem to server c TITLE БАааааа, DES: БАааа ,LOCATION: 56.839104,60.60825 URGENCY: 1
2024-02-11 16:50:52,358 - INFO - User dabyt (930547383) create problem
2024-02-11 16:50:57,530 - INFO - User dabyt (930547383) send problem to server c TITLE ddsf, DES: sdf ,LOCATION: 38.1716962,-85.7354076 URGENCY: 0
2024-02-11 16:51:09,902 - INFO - User dabyt (930547383) start bot
2024-02-11 16:51:24,820 - INFO - User dabyt (930547383) create problem
2024-02-11 16:51:31,291 - INFO - User dabyt (930547383) send problem to server c TITLE ds, DES: sdsd ,LOCATION: 44.6471761,-100.348761 URGENCY: 2
2024-02-11 16:55:05,187 - INFO - User dabyt (930547383) create problem
2024-02-11 16:55:12,659 - INFO - User dabyt (930547383) send problem to server c TITLE выыв, DES: выым ,LOCATION: 56.6517928,-111.2283896 URGENCY: 0
2024-02-11 16:57:49,164 - INFO - User dabyt (930547383) start bot
2024-02-11 16:58:23,965 - INFO - User dabyt (930547383) create problem
